Workbook

Sheet Master Tab
A1: Dairy_Annual_Report | F1: 22 AR Status | G1: Note | H1: APN Correct?
A2: A & M De Souza Dairy | F2: Y | G2: No Staff was assigned to this facility | H2: No
A3: Silva Dairy Farms #3A | F3: Y | G3: merged with Silva Dairy Farms #3B | H3: Yes
A4: Joe Borba Dairy Inc. | F4: Y | H4: No
A5: Ken Van Foeken Dairy #2 | F5: Y | H5: Yes
A6: Da Rosa Dairy | F6: Y | G6: under Dan's name | H6: Yes
A7: J_D Brasil Dairy | F7: Y | H7: Yes
A8: River Rock Ranch LLC | F8: Y | H8: Yes
A9: Double Cross #3 | F9: Y | H9: Yes
A10: Edward Nunes Dairy | F10: Y | G10: under Charles's name (It was uploaded to GT, np) | H10: Yes
A11: Gomes Dairy | F11: Y | H11: Yes
A12: Roest Family Dairy | F12: Y | H12: Yes
A13: Gil Tex Dairy | F13: Y | G13: Missing Signature | H13: No
A14: GJ Silva | F14: Y | G14: G J Silva #3 is merged with this dairy | H14: No | J14: N# of Non-Filer | K14: =COUNTIF(F2:F144, "N") -> 3
A15: Hilmar Holsteins Inc. | F15: Y | H15: Yes | J15: N# of Filer | K15: =COUNTIF(F2:F144, "Y") -> 131
A16: Jordao Dairy | F16: Y | G16: under Sean's name | H16: Yes
A17: Cross Creek Dairy | F17: Y | H17: Yes
A18: Double Cross #2 | F18: Y | H18: Yes
A19: LarryPetersonDairyFarms#2 | F19: Y | G19: under Dan's name | H19: Yes
A20: Fire_Lake Jerseys #2 | F20: Y | H20: No
A21: Lumar Dairy Farms | F21: Y | H21: Yes
A22: CMA Livestock | F22: Y | H22: Yes
A23: Fire Lakes Jerseys | F23: Y | G23: under Sean's name | H23: Yes
A24: Rick Jones Farms | F24: Y | H24: Yes
A25: Silveira Holsteins | F25: Y | H25: Yes
A26: Diamond B Dairy | F26: Y | H26: Yes
A27: Azevedo Dairy | F27: Y | H27: Yes
A28: Valsigna Dairy | F28: Y | H28: Yes
A29: WickstromJerseyFarmsInc. | F29: Y | H29: Yes
A30: Diniz Dairy | F30: Y | H30: Yes
A31: Crane Dairy Inc. | F31: Y | H31: Yes
A32: GM Silva Dairies #2 | F32: Y | H32: Yes
A33: Joe Oliveira Dairy | F33: Y | H33: Yes
A34: Vierra Dairy Farms #3 | F34: Y | H34: Yes
A35: Nelson Dairy | F35: Y | H35: Yes
... A41: T & M Borba Dairy | F41: Y | H41: Yes
A42: Oslo Dairy | F42: Y | H42: No | I42: Not signed
A43: Kronberg Facility | F43: Y | H43: Yes
A44: Ken Van Foeken Dairy | F44: Y | H44: Yes
A45: Amaral Dairy Farms | F45: Y | G45: John Avila confirmed that he will be sending AR in a week or 2 | H45: Yes
...

Sheet Dairy_Annual_Report
A1: REGION | B1: FACILITY ID | C1: FACILITY NAME | D1: PLACE TYPE | E1: PLACE SUBTYPE | F1: FACILITY TYPE | G1: AGENCY NAME | H1: AGENCY TYPE | I1: PLACE ADDRESS | J1: PLACE CITY | K1: PLACE ZIP | L1: PLACE COUNTY | M1: LATITUDE DECIMAL DEGREES | N1: LONGITUDE DECIMAL DEGREES | O1: SIC DESC 1 | P1: NAICS DESC 1 | Q1: PROGRAM | R1: PROGRAM CATEGORY | S1: WDID | T1: REG MEASURE ID | U1: REG MEASURE TYPE | V1: REG MEASURE TITLE | W1: REG MEASURE DESCRIPTION | X1: ORDER # | Y1: STATUS | Z1: STATUS DATE | AA1: EFFECTIVE DATE | AB1: EXPIRATION/REVIEW DATE | AC1: FEE CODE | AD1: STAFF ASSIGNED | AE1: # OF STAFF ASSIGNED | AF1: APPLICATION FEE AMT RECEIVED | AG1: CAFO SUBTYPE | AH1: CAFO TYPE | AI1: CAFO POPULATION | AJ1: QUALITY ASSURANCE | AK1: Animal Equivalent Units (AEU) | AL1: AR Recieve Date | AM1: Consultant | AN1: Signature | AO1: OwnOp = CIWQS | AP1: Milk Cows | AQ1: Dry Cows | AR1: Bred Heifers 15-24 mo | AS1: Heifers 7-14 mo | AT1: Calves 4-6 mo | AU1: Calves 0-3 mo | AV1: Mature Herd Size | AW1: Max Allowed Herd Size | AX1: Billing Change | AY1: Expansion | AZ1: WW Exports | BA1: Manure Exports | BB1: Manure Manifests | BC1: Imports | BD1: Total Acreage | BE1: Missing Harvest Data | BF1: Low Water Application | BG1: High Harvest N Data | BH1: Low Harvest Rates | BI1: High N Ratio | BJ1: Domestic Wells w/ N-NO3 > 10 | BK1: GW lab samples | BL1: Missing Manure Samples | BM1: Missing Wastewater Samples | BN1: Revised Site Plans | BO1: Additional Notes/Concerns
A2: 5S | B2: 203907 | C2: A & M De Souza Dairy | D2: Growing | E2: Animal Feeding | F2: Agricultural | G2: De Sousa, Armelin & Maria | H2: Privately-Owned Business | I2: 3030 South Central Avenue | J2: Turlock | K2: 95380 | L2: Stanislaus | M2: 37.46564 | N2: -120.95585 | O2: Dairy Farms | P2: Dairy Cattle and Milk Production | Q2: ANIWSTCOWS | R2: ANIMALWASTE | S2: 5B50NC00226 | T2: 335259 | U2: Enrollee - WDR | V2: Enrollee Under Dairy GO for De Sousa, Armelin & Maria - A & M De Souza Dairy | X2: R5-2013-0122 | Y2: Active | Z2: 42181 | AA2: 39262 | AB2: 10/02/2018 | AC2: 10 - Confined animal feeding facility | AD2: Lamyae Zinebi | AE2: 1 | AF2: 2725 | AG2: Mature dairy cattle | AH2: Dairies | AI2: 1539 | AJ2: N
A3: 5S | B3: 209495 | C3: Silva Dairy Farms #3A | D3: Growing | E3: Animal Feeding | F3: Agricultural | G3: Silva, Manuel | H3: Privately-Owned Business | I3: 1499 North Edminster Road | J3: Stevinson | K3: 95374 | L3: Merced | M3: 37.311085 | N3: -120.89674 | O3: Dairy Farms | P3: Dairy Cattle and Milk Production | Q3: ANIWSTCOWS | R3: ANIMALWASTE | S3: 5B24NC00263 | T3: 334890 | U3: Enrollee - WDR | V3: Enrollee Under Dairy GO for Silva, Manuel - Silva Dairy Farms #3A | X3: R5-2013-0122 | Y3: Active | Z3: 43412 | AA3: 39262 | AB3: 10/02/2018 | AC3: 10 - Confined animal feeding facility | AD3: Lamyae Zinebi | AE3: 1 | AF3: 654 | AG3: Mature dairy cattle | AH3: Dairies | AI3: 1605 | AJ3: Y
A4: 5S | B4: 210049 | C4: Joe Borba Dairy Inc. | D4: Growing | E4: Animal Feeding | F4: Agricultural | G4: Joe Borba Dairy Inc | H4: Privately-Owned Business | I4: 3431 South Moffett Road | J4: Turlock | K4: 95380 | L4: Stanislaus | M4: 37.45977 | N4: -120.95136 | O4: Dairy Farms | P4: Dairy Cattle and Milk Production | Q4: ANIWSTCOWS | R4: ANIMALWASTE | S4: 5B50NC00262 | T4: 335295 | U4: Enrollee - WDR | V4: Enrollee Under Dairy Gen Order for Joe Borba Dairy Inc | X4: R5-2013-0122 | Y4: Active | Z4: 42181 | AA4: 39262 | AB4: 10/02/2018 | AC4: 15 - WDRs pending rescission | AD4: Lamyae Zinebi | AE4: 1 | AF4: 654 | AG4: Heifers (non dairy affiliated) | AH4: Dairies | AI4: 85 | AJ4: N
A5: 5S | B5: 218891 | C5: Ken Van Foeken Dairy #2 | D5: Growing | E5: Animal Feeding | F5: Agricultural | G5: Van Foeken, Kenneth L | H5: Privately-Owned Business | I5: 9375 North Washington Road | J5: Hilmar | K5: 95324 | L5: Merced | M5: 37.42486 | N5: -120.90462 | O5: Dairy Farms | P5: Dairy Cattle and Milk Production | Q5: ANIWSTCOWS | R5: ANIMALWASTE | S5: 5B24NC00160 | T5: 334789 | U5: Enrollee - WDR | V5: Enrollee Under Dairy GO for Van Foeken, Kenneth L. - Ken Van Foeken Dairy #2 | X5: R5-2013-0122 | Y5: Active | Z5: 43411 | AA5: 39262 | AB5: 10/02/2018 | AC5: 10 - Confined animal feeding facility | AD5: Lamyae Zinebi | AE5: 1 | AF5: 654 | AG5: Mature dairy cattle | AH5: Dairies | AI5: 651 | AJ5: Y
A6: 5S | B6: 218992 | C6: Da Rosa Dairy | D6: Growing | E6: Animal Feeding | F6: Agricultural | G6: Da Rosa, Luis & Olivia | H6: Privately-Owned Business | I6: 1131 Story Road | J6: Turlock | K6: 95380 | L6: Stanislaus | M6: 37.48168 | N6: -120.78966 | O6: Dairy Farms | Q6: ANIWSTCOWS | R6: ANIMALWASTE | S6: 5B50NC00277 | T6: 335310 | U6: Enrollee - WDR | V6: Enrollee Under Dairy GO for Da Rosa, Luis & Olivia | X6: R5-2013-0122 | Y6: Active | Z6: 42181 | AA6: 39262 | AB6: 10/02/2018 | AC6: 10 - Confined animal feeding facility | AD6: Lamyae Zinebi | AE6: 1 | AF6: 654 | AG6: Mature dairy cattle | AH6: Dairies | AI6: 115 | AJ6: N
A7: 5S | B7: 219290 | C7: J_D Brasil Dairy | D7: Growing | E7: Animal Feeding | F7: Agricultural | G7: Brasil, Danny | H7: Privately-Owned Business | I7: 5600 Clayton Road | J7: Turlock | K7: 95380 | L7: Stanislaus | M7: 37.47989 | N7: -120.91512 | O7: Dairy Farms | Q7: ANIWSTCOWS | R7: ANIMALWASTE | S7: 5B50NC00103 | T7: 335136 | U7: Enrollee - WDR | V7: Enrollee Under Dairy Gen Order for Brasil, Danny, J-D Brasil Dairy | W7: 22 June 2012- The RB has approved operator transfer for Danny Brasil for the J-D Brasil Dairy.-Dy | X7: R5-2013-0122 | Y7: Active | Z7: 42173 | AA7: 39262 | AB7: 10/02/2018 | AC7: 10 - Confined animal feeding facility | AD7: Lamyae Zinebi | AE7: 1 | AF7: 654 | AG7: Mature dairy cattle | AH7: Dairies | AI7: 410 | AJ7: N
A8: 5S | B8: 220560 | C8: River Rock Ranch LLC | D8: Growing | E8: Animal Feeding | F8: Agricultural | G8: River Rock Ranch, LLC | H8: Privately-Owned Business | I8: 22846 West Second Avenue | J8: Stevinson | K8: 95374 | L8: Merced | M8: 37.33335 | N8: -120.91002 | O8: Dairy Farms | P8: Dairy Cattle and Milk Production | Q8: ANIWSTCOWS | R8: ANIMALWASTE | S8: 5B24NC00272 | T8: 334899 | U8: Enrollee - WDR | V8: Enrollee Under Dairy GO for River Rock Ranch, LLC | X8: R5-2013-0122 | Y8: Active | Z8: 44453 | AA8: 39262 | AB8: 10/02/2018 | AC8: 10 - Confined animal feeding facility | AD8: Lamyae Zinebi | AE8: 1 | AF8: 1308 | AG8: Mature dairy cattle | AH8: Dairies | AI8: 1380 | AJ8: N
A9: 5S | B9: 221709 | C9: Double Cross #3 | D9: Growing | E9: Animal Feeding | F9: Agricultural | G9: Coelho, Joe & Louise | H9: Privately-Owned Business | I9: 11071 Youngstown Road | J9: Turlock | K9: 95380 | L9: Merced | M9: 37.44974 | N9: -120.824 | O9: Dairy Farms | P9: Dairy Cattle and Milk Production | Q9: ANIWSTCOWS | R9: ANIMALWASTE | S9: 5C245033001 | T9: 354671 | U9: Enrollee - WDR | V9: Enrollee Under Dairy GO for Ahlem, Mark - Double Cross #3 | W9: 11/23/2016 - Op. has changed (was Dominic Coehlo) - ak 08/03/2011 - the Board approves the request for owner/operator transfer effective the date of the letter. Coelho, Joe & Louise, are now authorized to oversee the operation of the dairy - jv | X9: R5-2013-0122 | Y9: Active | Z9: 43417 | AA9: 39262 | AB9: 10/02/2018 | AC9: 10 - Confined animal feeding facility | AD9: Lamyae Zinebi | AE9: 1 | AG9: Mature dairy cattle | AH9: Dairies | AI9: 402 | AJ9: Y
A10: 5S | B10: 222320 | C10: Edward Nunes Dairy | D10: Growing | E10: Animal Feeding | F10: Agricultural | G10: Nunes, Edward | H10: Privately-Owned Business | I10: 17399 East Avena Road | J10: Escalon | K10: 95320 | L10: San Joaquin | M10: 37.84172 | N10: -121.09854 | O10: Dairy Farms | P10: Dairy Cattle and Milk Production | Q10: ANIWSTCOWS | R10: ANIMALWASTE | S10: 5B39NC00062 | T10: 334959 | U10: Enrollee - WDR | V10: Enrollee Under Dairy GO for Nunes, Edward - Edward Nunes Dairy | X10: R5-2013-0122 | Y10: Active | Z10: 43417 | AA10: 39262 | AB10: 10/02/2018 | AC10: 10 - Confined animal feeding facility | AD10: Lamyae Zinebi | AE10: 1 | AF10: 1308 | AG10: Mature dairy cattle | AH10: Dairies | AI10: 2129 | AJ10: Y
A11: 5S | B11: 224219 | C11: Gomes Dairy | D11: Growing | E11: Animal Feeding | F11: Agricultural | G11: Gomes Dairy | H11: Privately-Owned Business | I11: 9735 Washington Road | J11: Hilmar | K11: 95324 | L11: Merced | M11: 37.42819 | N11: -120.90548 | O11: Dairy Farms | P11: Dairy Cattle and Milk Production | Q11: ANIWSTCOWS | R11: ANIMALWASTE | S11: 5B24NC00161 | T11: 334790 | U11: Enrollee - WDR | V11: Enrollee Under Dairy GO for Gomes Dairy | W11: 3/19/2019 - Chang of Owner/Operator. -JY | X11: R5-2013-0122 | Y11: Active | Z11: 43549 | AA11: 39262 | AB11: 10/02/2018 | AC11: 10 - Confined animal feeding facility | AD11: Lamyae Zinebi | AE11: 1 | AF11: 654 | AG11: Mature dairy cattle | AH11: Dairies | AI11: 715 | AJ11: N
A12: 5S | B12: 226601 | C12: Roest Family Dairy | D12: Growing | E12: Animal Feeding | F12: Agricultural | G12: Roest, Aire | H12: Privately-Owned Business | I12: 2472 Gates Road | J12: Modesto | K12: 95358 | L12: Stanislaus | M12: 37.67324 | N12: -121.15929 | O12: Dairy Farms | P12: Dairy Cattle and Milk Production | Q12: ANIWSTCOWS | R12: ANIMALWASTE | S12: 5B50NC00111 | T12: 335144 | U12: Enrollee - WDR | V12: Enrollee Under Dairy GO for Roest, Arie | X12: R5-2013-0122 | Y12: Active | Z12: 42173 | AA12: 39262 | AB12: 10/02/2018 | AC12: 10 - Confined animal feeding facility | AD12: Lamyae Zinebi | AE12: 2 | AF12: 1308 | AG12: Mature dairy cattle | AH12: Dairies | AI12: 1102 | AJ12: N
A13: 5S | B13: 227158 | C13: Gil Tex Dairy | D13: Growing | E13: Animal Feeding | F13: Agricultural | G13: Teixeira, Gilbert & Linda | H13: Privately-Owned Business | I13: 5601 Mountain View Road | J13: Turlock | K13: 95382 | L13: Stanislaus | M13: 37.54581 | N13: -120.88142 | O13: Dairy Farms | P13: Dairy Cattle and Milk Production | Q13: ANIWSTCOWS | R13: ANIMALWASTE | S13: 5C505022001 | T13: 354688 | U13: Enrollee - WDR | V13: Enrollee Under Dairy GO for Teixeira, Gilbert & Linda - Gil Tex Dairy | X13: R5-2013-0122 | Y13: Active | Z13: 43353 | AA13: 39262 | AB13: 10/02/2018 | AC13: 10 - Confined animal feeding facility | AD13: Lamyae Zinebi | AE13: 1 | AG13: Mature dairy cattle | AH13: Dairies | AI13: 490 | AJ13: N
A14: 5S | B14: 227211 | C14: GJ Silva | D14: Growing | E14: Animal Feeding | F14: Agricultural | G14: Latters, Susan | H14: Privately-Individual | I14: 3107 South Prairie Flower Road | J14: Turlock | K14: 95380 | L14: Stanislaus | M14: 37.46541 | N14: -120.93535 | O14: Dairy Farms | P14: Dairy Cattle and Milk Production | Q14: ANIWSTCOWS | R14: ANIMALWASTE | S14: 5B50NC00275 | T14: 335308 | U14: Enrollee - WDR | V14: Enrollee Under Dairy GO for G J Silva & Sons, Inc. | W14: 03/19/2019 - Owner/ Operator transfer. - JY 12/18/2018 GJ Silva Heifer Facility (3630 S Prairie Flower Road) merged with this dairy. -JY | X14: R5-2013-0122 | Y14: Active | Z14: 43570 | AA14: 39262 | AB14: 10/02/2018 | AC14: 10 - Confined animal feeding facility | AD14: Lamyae Zinebi | AE14: 1 | AF14: 4260 | AG14: Mature dairy cattle | AH14: Dairies | AI14: 2583 | AJ14: N
A15: 5S | B15: 230428 | C15: Hilmar Holsteins Inc. | D15: Growing | E15: Animal Feeding | F15: Agricultural | G15: Matheron, Aaron dba Hilmar Holsteins Inc | H15: Privately-Owned Business | I15: 21859 Crane Avenue | J15: Hilmar | K15: 95324 | L15: Merced | M15: 37.38274 | N15: -120.88425 | O15: Dairy Farms | P15: Dairy Cattle and Milk Production | Q15: ANIWSTCOWS | R15: ANIMALWASTE | S15: 5B24NC00131 | T15: 334760 | U15: Enrollee - WDR | V15: Enrollee Under Dairy GO for Matheron, Aaron dba Hilmar Holsteins Inc. | W15: 10/08/2018 Hilmar Holsteins Heifer Corral #2 is now merged with this dairy. -JY 10/08/2018 Hilmar Holsteins Heifer Corral #1 is now merged with this dairy. -JY 7/3/2015 - Dairy located at 6271 Columbus Avenue is now merged with this dairy. Total animal count of 2829. -JY 10/14/14: OP/owner changed to Matheron, Aaron dba Hilmar Holsteins Inc. - HT | X15: R5-2013-0122 | Y15: Active | Z15: 43510 | AA15: 39262 | AB15: 10/02/2018 | AC15: 10 - Confined animal feeding facility | AD15: Lamyae Zinebi | AE15: 1 | AF15: 2725 | AG15: Mature dairy cattle | AH15: Dairies | AI15: 2400 | AJ15: Y
A16: 5S | B16: 233735 | C16: Jordao Dairy | D16: Growing | E16: Animal Feeding | F16: Agricultural | G16: Jordao, Joe & Jose | H16: Privately-Owned Business | I16: 6025 South Central Avenue | J16: Turlock | K16: 95380 | L16: Stanislaus | M16: 37.436412 | N16: -120.9586 | O16: Dairy Farms | P16: Dairy Cattle and Milk Production | Q16: ANIWSTCOWS | R16: ANIMALWASTE | S16: 5B50NC00221 | T16: 335254 | U16: Enrollee - WDR | V16: Enrollee Under Dairy GO for Jordao, Joe and Jose | X16: R5-2013-0122 | Y16: Active | Z16: 42181 | AA16: 39262 | AB16: 10/02/2018 | AC16: 10 - Confined animal feeding facility | AD16: Lamyae Zinebi | AE16: 1 | AF16: 1308 | AG16: Mature dairy cattle | AH16: Dairies | AI16: 920 | AJ16: Y
A17: 5S | B17: 233749 | C17: Cross Creek Dairy | D17: Growing | E17: Animal Feeding | F17: Agricultural | G17: Branco, Joe & Cathy | H17: Privately-Owned Business | I17: 7965 Washington Road | J17: Hilmar | K17: 95324 | L17: Merced | M17: 37.40419 | N17: -120.90492 | O17: Dairy Farms | P17: Dairy Cattle and Milk Production | Q17: ANIWSTCOWS | R17: ANIMALWASTE | S17: 5B24NC00159 | T17: 334788 | U17: Enrollee - WDR | V17: Enrollee Under Dairy Gen Order for Branco, Joe & Cathy - Cross Creek Dairy | X17: R5-2013-0122 | Y17: Active | Z17: 43411 | AA17: 39262 | AB17: 10/02/2018 | AC17: 10 - Confined animal feeding facility | AD17: Lamyae Zinebi | AE17: 1 | AF17: 654 | AG17: Mature dairy cattle | AH17: Dairies | AI17: 780 | AJ17: Y
A18: 5S | B18: 233757 | C18: Double Cross #2 | D18: Growing | E18: Animal Feeding | F18: Agricultural | G18: Joe Coelho Dairy | H18: Privately-Owned Business | I18: 18637 East Bradbury Road | J18: Turlock | K18: 95380 | L18: Merced | M18: 37.44886 | N18: -120.82427 | O18: Dairy Farms | P18: Dairy Cattle and Milk Production | Q18: ANIWSTCOWS | R18: ANIMALWASTE | S18: 5B24NC00277 | T18: 334904 | U18: Enrollee - WDR | V18: Enrollee Under Dairy GO for Coehlo, Joe - Double Cross #2 | W18: 11/23/2016 - Op. has changed (was Coehlo, Joe) - ak | X18: R5-2013-0122 | Y18: Active | Z18: 43417 | AA18: 39262 | AB18: 10/02/2018 | AC18: 10 - Confined animal feeding facility | AD18: Lamyae Zinebi | AE18: 1 | AF18: 654 | AG18: Mature dairy cattle | AH18: Dairies | AI18: 637 | AJ18: Y
A19: 5S | B19: 233895 | C19: LarryPetersonDairyFarms#2 | D19: Growing | E19: Animal Feeding | F19: Agricultural | G19: Leonardo, John Dairy | H19: Privately-Owned Business | I19: 20775 West American Avenue | J19: Hilmar | K19: 95324 | L19: Merced | M19: 37.40978 | N19: -120.86592 | O19: Dairy Farms | P19: Dairy Cattle and Milk Production | Q19: ANIWSTCOWS | R19: ANIMALWASTE | S19: 5B24NC00107 | T19: 334740 | U19: Enrollee - WDR | V19: Enrollee Under Dairy GO for John Leonardo - Larry B. Peterson Dairy Farms #2 | W19: 11/23/2016 - Op. has changed (were Dominic & Mary Coelho) - ak | X19: R5-2013-0122 | Y19: Active | Z19: 43411 | AA19: 39262 | AB19: 10/02/2018 | AC19: 10 - Confined animal feeding facility | AD19: Lamyae Zinebi | AE19: 1 | AF19: 654 | AG19: Mature dairy cattle | AH19: Dairies | AI19: 381 | AJ19: Y
A20: 5S | B20: 233934 | C20: Fire_Lake Jerseys #2 | D20: Growing | E20: Animal Feeding | F20: Agricultural | G20: Thomas, Rhonda | H20: Privately-Owned Business | I20: 10408 West Bradbury Road | J20: Turlock | K20: 95380 | L20: Stanislaus | M20: 37.449239 | N20: -120.96768 | O20: Dairy Farms | P20: Dairy Cattle and Milk Production | Q20: ANIWSTCOWS | R20: ANIMALWASTE | S20: 5B50NC00289 | T20: 335322 | U20: Enrollee - WDR | V20: Enrollee Under Dairy GO for Thomas, Rhonda, Fire-Lake Jerseys #2 | X20: R5-2013-0122 | Y20: Active | Z20: 43068 | AA20: 39262 | AB20: 10/02/2018 | AC20: 10 - Confined animal feeding facility | AD20: Lamyae Zinebi | AE20: 1 | AF20: 654 | AG20: Heifers (non dairy affiliated) | AH20: Dairies | AI20: 740 | AJ20: N
A21: 5S | B21: 237694 | C21: Lumar Dairy Farms | D21: Growing | E21: Animal Feeding | F21: Agricultural | G21: Borba, Luis & Maria | H21: Privately-Owned Business | I21: 7215 South Prairie Flower Road | J21: Turlock | K21: 95380 | L21: Stanislaus | M21: 37.423154 | N21: -120.93134 | O21: Dairy Farms | P21: Dairy Cattle and Milk Production | Q21: ANIWSTCOWS | R21: ANIMALWASTE | S21: 5B50NC00269 | T21: 335302 | U21: Enrollee - WDR | V21: Enrollee Under Dairy Gen Order for Borba, Luis & Maria, Lumar Dairy Farms | X21: R5-2013-0122 | Y21: Active | Z21: 42181 | AA21: 39262 | AB21: 10/02/2018 | AC21: 10 - Confined animal feeding facility | AD21: Lamyae Zinebi | AE21: 1 | AF21: 2725 | AG21: Mature dairy cattle | AH21: Dairies | AI21: 2100 | AJ21: Y
A22: 5S | B22: 239367 | C22: CMA Livestock | D22: Growing | E22: Animal Feeding | F22: Agricultural | G22: Luis, Manuel S. & Bernardet | H22: Privately-Owned Business | I22: 19051 West Williams Avenue | J22: Hilmar | K22: 95324 | L22: Merced | M22: 37.389598 | N22: -120.83234 | O22: Dairy Farms | P22: Dairy Cattle and Milk Production | Q22: ANIWSTCOWS | R22: ANIMALWASTE | S22: 5B24NC00163 | T22: 334792 | U22: Enrollee - WDR | V22: Enrollee Under Dairy GO for Manuel Luis - CMA Livestock | W22: 11/23/2016 - Op. has changed (was Luis, Manuel S.) - ak | X22: R5-2013-0122 | Y22: Active | Z22: 43411 | AA22: 39262 | AB22: 10/02/2018 | AC22: 10 - Confined animal feeding facility | AD22: Lamyae Zinebi | AE22: 1 | AF22: 1308 | AG22: Mature dairy cattle | AH22: Dairies | AI22: 684 | AJ22: Y
A23: 5S | B23: 251780 | C23: Fire Lakes Jerseys | D23: Growing | E23: Animal Feeding | F23: Agricultural | G23: Sanders, Scott | H23: Privately-Owned Business | I23: 11301 West Bradbury Road | J23: Turlock | K23: 95380 | L23: Stanislaus | M23: 37.44931 | N23: -120.97775 | O23: Dairy Farms | P23: Dairy Cattle and Milk Production | Q23: ANIWSTCOWS | R23: ANIMALWASTE | S23: 5B50NC00308 | T23: 364501 | U23: Enrollee - WDR | V23: Enrollee Under Dairy GO for Sanders, Scott & Sharalee | W23: On 12/05/08, we received a request for owner / operator transfer approval for SAS Dairy #4. The owner/operator transfer approval was issued to take effect on 03/16/09 - jv | X23: R5-2013-0122 | Y23: Active | Z23: 42181 | AA23: 39262 | AB23: 10/02/2018 | AC23: 10 - Confined animal feeding facility | AD23: Lamyae Zinebi | AE23: 1 | AG23: Mature dairy cattle | AH23: Dairies | AI23: 278 | AJ23: Y
A24: 5S | B24: 252667 | C24: Rick Jones Farms | D24: Growing | E24: Animal Feeding | F24: Agricultural | G24: Jones Farms | H24: Privately-Owned Business | I24: 1511 Van Clief Road | J24: Stevinson | K24: 95374 | L24: Merced | M24: 37.30955 | N24: -120.83303 | O24: Dairy Farms | P24: Dairy Cattle and Milk Production | Q24: ANIWSTCOWS | R24: ANIMALWASTE | S24: 5C245037001 | T24: 354675 | U24: Enrollee - WDR | V24: Enrollee Under Dairy GO for Rick Jones Farms | W24: 10/08/2018 Jones Farms Heifer Facility is now merged with this dairy. -JY | X24: R5-2013-0122 | Y24: Active | Z24: 43510 | AA24: 39262 | AB24: 10/02/2018 | AC24: 10 - Confined animal feeding facility | AD24: Lamyae Zinebi | AE24: 1 | AG24: Mature dairy cattle | AH24: Dairies | AI24: 690
A25: 5S | B25: 257092 | C25: Silveira Holsteins | D25: Growing | E25: Animal Feeding | F25: Agricultural | G25: Silveira, Manuel | H25: Privately-Owned Business | I25: 23356 Short Avenue | J25: Hilmar | K25: 95324 | L25: Merced | M25: 37.42641 | N25: -120.91051 | O25: Dairy Farms | P25: Dairy Cattle and Milk Production | Q25: ANIWSTCOWS | R25: ANIMALWASTE | S25: 5B24NC00149 | T25: 334778 | U25: Enrollee - WDR | V25: Enrollee Under Dairy GO for Silveira, Manuel - Silveira Holsteins | W25: 1/17/2019 - Dairy located at 5531 Ehrlich Road (Former Blue Island Jerseys), Turlock is now merged with this dairy. Total Animal population of 735. - JY | X25: R5-2013-0122 | Y25: Active | Z25: 43510 | AA25: 39262 | AB25: 10/02/2018 | AC25: 10 - Confined animal feeding facility | AD25: Lamyae Zinebi | AE25: 1 | AF25: 654 | AG25: Mature dairy cattle | AH25: Dairies | AI25: 679 | AJ25: Y
A26: 5S | B26: 263088 | C26: Diamond B Dairy | D26: Growing | E26: Animal Feeding | F26: Agricultural | G26: Brasil, John | H26: Privately-Individual | I26: 3137 East Tuolumne Road | J26: Ceres | K26: 95307 | L26: Stanislaus | M26: 37.51451 | N26: -120.9356 | O26: Dairy Farms | Q26: ANIWSTCOWS | R26: ANIMALWASTE | S26: 5B50NC00300 | T26: 353697 | U26: Enrollee - WDR | V26: Enrollee Under Dairy GO for Meneses, Adeline - Diamond B Dairy | W26: 22 June 2012- The Board has approved operator transfer for John Brasil as the operator at the Diamond B Dairy.-Dy | X26: R5-2013-0122 | Y26: Active | Z26: 43579 | AA26: 39262 | AB26: 10/02/2018 | AC26: 10 - Confined animal feeding facility | AD26: Lamyae Zinebi | AE26: 1 | AF26: 0 | AG26: Mature dairy cattle | AH26: Dairies | AI26: 679 | AJ26: N
A27: 5S | B27: 264484 | C27: Azevedo Dairy | D27: Growing | E27: Animal Feeding | F27: Agricultural | G27: Azevedo, Tiberio & Rosa | H27: Privately-Owned Business | I27: 21480 August Avenue | J27: Hilmar | K27: 95324 | L27: Merced | M27: 37.418948 | N27: -120.87684 | O27: Dairy Farms | P27: Dairy Cattle and Milk Production | Q27: ANIWSTCOWS | R27: ANIMALWASTE | S27: 5B24NC00111 | T27: 334744 | U27: Enrollee - WDR | V27: Enrollee Under Dairy Gen Order for Azevedo, Tiberio & Rosa - Azevedo Dairy | X27: R5-2013-0122 | Y27: Active | Z27: 43411 | AA27: 39262 | AB27: 10/02/2018 | AC27: 10 - Confined animal feeding facility | AD27: Lamyae Zinebi | AE27: 1 | AF27: 1308 | AG27: Mature dairy cattle | AH27: Dairies | AI27: 930 | AJ27: Y
A28: 5S | B28: 272502 | C28: Valsigna Dairy | D28: Growing | E28: Animal Feeding | F28: Agricultural | G28: Wickstrom, Tim & Vern | H28: Privately-Owned Business | I28: 6071 North Larson Avenue | J28: Hilmar | K28: 95324 | L28: Merced | M28: 37.38248 | N28: -120.85019 | O28: Dairy Farms | P28: Dairy Cattle and Milk Production | Q28: ANIWSTCOWS | R28: ANIMALWASTE | S28: 5B24NC00144 | T28: 334773 | U28: Enrollee - WDR | V28: Enrollee Under Dairy GO for Wickstrom, Tim & Vern - Valsigna Dairy | X28: R5-2013-0122 | Y28: Active | Z28: 43411 | AA28: 39262 | AB28: 10/02/2018 | AC28: 10 - Confined animal feeding facility | AD28: Lamyae Zinebi | AF28: 2725 | AG28: Mature dairy cattle | AH28: Dairies | AI28: 2940 | AJ28: Y
A29: 5S | B29: 705196 | C29: WickstromJerseyFarmsInc. | D29: Growing | E29: Animal Feeding | F29: Agricultural | G29: Wickstrom, Mike | H29: Privately-Owned Business | I29: 5638 Columbus Avenue | J29: Hilmar | K29: 95324 | L29: Merced | M29: 37.36976 | N29: -120.86883 | O29: Dairy Farms | P29: Dairy Cattle and Milk Production | Q29: ANIWSTCOWS | R29: ANIMALWASTE | S29: 5B24NC00123 | T29: 333921 | U29: Enrollee - WDR | V29: Enrollee Under Dairy GO for Wickstrom, Mike - Wickstrom Jersey Farms, Inc. | X29: R5-2013-0122 | Y29: Active | Z29: 43411 | AA29: 39262 | AB29: 10/02/2018 | AC29: 10 - Confined animal feeding facility | AD29: Lamyae Zinebi | AE29: 1 | AF29: 2725 | AG29: Mature dairy cattle | AH29: Dairies | AI29: 2750 | AJ29: Y
A30: 5S | B30: 705203 | C30: Diniz Dairy | D30: Growing | E30: Animal Feeding | F30: Agricultural | G30: Diniz, Antonio V & Maria | H30: Privately-Owned Business | I30: 9558 Columbus Avenue | J30: Hilmar | K30: 95324 | L30: Merced | M30: 37.42795 | N30: -120.86571 | O30: Dairy Farms | P30: Dairy Cattle and Milk Production | Q30: ANIWSTCOWS | R30: ANIMALWASTE | S30: 5B24NC00126 | T30: 333932 | U30: Enrollee - WDR | V30: Enrollee Under Dairy GO for Diniz, Antonio V & Maria - Diniz Dairy | X30: R5-2013-0122 | Y30: Active | Z30: 43411 | AA30: 39262 | AB30: 10/02/2018 | AC30: 10 - Confined animal feeding facility | AD30: Lamyae Zinebi | AE30: 1 | AF30: 654 | AG30: Mature dairy cattle | AH30: Dairies | AI30: 550 | AJ30: Y
A31: 5S | B31: 705219 | C31: Crane Dairy Inc. | D31: Growing | E31: Animal Feeding | F31: Agricultural | G31: Crane Dairy, Inc | H31: Privately-Owned Business | I31: 20633 West Crane Avenue | J31: Hilmar | K31: 95324 | L31: Merced | M31: 37.38259 | N31: -120.86194 | O31: Dairy Farms | P31: Dairy Cattle and Milk Production | Q31: ANIWSTCOWS | R31: ANIMALWASTE | S31: 5B24NC00128 | T31: 334757 | U31: Enrollee - WDR | V31: Enrollee Under Dairy GO for Leroy Souza - Crane Dairy, Inc | W31: 10/08/2018 Crane Heifer Feedlot #2 (6404 Columbus Avenue) is now merged with this dairy. -JY 10/08/2018 Crane Heifer Feedlot #1 (6736 Columbus Avenue) with this Dairy. -JY 11/23/2016 - Ow/Op have changed (were Souza, Leroy & Phillip) - ak | X31: R5-2013-0122 | Y31: Active | Z31: 43508 | AA31: 39262 | AB31: 10/02/2018 | AC31: 10 - Confined animal feeding facility | AD31: Lamyae Zinebi | AE31: 1 | AF31: 654 | AG31: Heifers (non dairy affiliated) | AH31: Dairies | AI31: 968 | AJ31: Y
A32: 5S | B32: 705229 | C32: GM Silva Dairies #2 | D32: Growing | E32: Animal Feeding | F32: Agricultural | G32: Silva, George & Margaret | H32: Privately-Owned Business | I32: 20316 West Crane Avenue | J32: Hilmar | K32: 95324 | L32: Merced | M32: 37.38259 | N32: -120.85601 | O32: Dairy Farms | P32: Dairy Cattle and Milk Production | Q32: ANIWSTCOWS | R32: ANIMALWASTE | S32: 5B24NC00129 | T32: 334758 | U32: Enrollee - WDR | V32: Enrollee Under Dairy GO for Silva, George & Margaret - GM Silva Dairies #2 | W32: 11/23/2016 - Owner and operator have changed (was Silva, Manuel) - ak 02/14/2020 - Dairy at 20633 Turner Ave, Hilmar is now merged with this dairy. Total Animal Population of 1467 - SP | X32: R5-2013-0122 | Y32: Active | Z32: 43880 | AA32: 39262 | AB32: 10/02/2018 | AC32: 10 - Confined animal feeding facility | AD32: Lamyae Zinebi | AE32: 1 | AF32: 654 | AG32: Mature dairy cattle | AH32: Dairies | AI32: 1461 | AJ32: Y
A33: 5S | B33: 705233 | C33: Joe Oliveira Dairy | D33: Growing | E33: Animal Feeding | F33: Agricultural | G33: Oliveira, Joe | H33: Privately-Owned Business | I33: 19104 Crane Avenue | J33: Hilmar | K33: 95324 | L33: Merced | M33: 37.38237 | N33: -120.83311 | O33: Dairy Farms | P33: Dairy Cattle and Milk Production | Q33: ANIWSTCOWS | R33: ANIMALWASTE | S33: 5B24NC00130 | T33: 334759 | U33: Enrollee - WDR | V33: Enrollee Under Dairy GO for Oliveira, Joe - Joe Oliveira Dairy | X33: R5-2013-0122 | Y33: Active | Z33: 42172 | AA33: 39262 | AB33: 10/02/2018 | AC33: 10 - Confined animal feeding facility | AD33: Lamyae Zinebi | AE33: 1 | AF33: 1308 | AG33: Mature dairy cattle | AH33: Dairies | AI33: 1270 | AJ33: Y
A34: 5S | B34: 705238 | C34: Vierra Dairy Farms #3 | D34: Growing | E34: Animal Feeding | F34: Agricultural | G34: Ferreira, Eleanor | H34: Privately-Individual | I34: 7884 Faith Home Road | J34: Hilmar | K34: 95324 | L34: Merced | M34: 37.40304 | N34: -120.92265 | O34: Dairy Farms | P34: Dairy Cattle and Milk Production | Q34: ANIWSTCOWS | R34: ANIMALWASTE | S34: 5B24NC00133 | T34: 334762 | U34: Enrollee - WDR | V34: Enrollee Under Dairy Gen Order for Ferreira, Eleanor - Vierra Dairy Farms #3 | W34: 10/19/18 - Operator transfer - JY | X34: R5-2013-0122 | Y34: Active | Z34: 43392 | AA34: 39262 | AB34: 10/02/2018 | AC34: 10 - Confined animal feeding facility | AD34: Lamyae Zinebi | AE34: 1 | AF34: 654 | AG34: Mature dairy cattle | AH34: Dairies | AI34: 321 | AJ34: N
A35: 5S | B35: 705241 | C35: Nelson Dairy | D35: Growing | E35: Animal Feeding | F35: Agricultural | G35: Joyce W. Nelson and Trust | H35: Privately-Owned Business | I35: 19481 Geer Avenue | J35: Hilmar | K35: 95324 | L35: Merced | M35: 37.39689 | N35: -120.84006 | O35: Dairy Farms | P35: Dairy Cattle and Milk Production | Q35: ANIWSTCOWS | R35: ANIMALWASTE | S35: 5B24NC00134 | T35: 334763 | U35: Enrollee - WDR | V35: Enrollee Under Dairy GO for Joyce W. Nelson and Trust - Nelson Dairy | X35: R5-2013-0122 | Y35: Active | Z35: 43411 | AA35: 39262 | AB35: 10/02/2018 | AC35: 10 - Confined animal feeding facility | AD35: Lamyae Zinebi | AE35: 1 | AF35: 327 | AG35: Heifers (non dairy affiliated) | AH35: Dairies | AI35: 177 | AJ35: N
A36: 5S | B36: 705247 | C36: Mario&ChristinaNunesDairy | D36: Growing | E36: Animal Feeding | F36: Agricultural | G36: Jorge, Luis & Maria | H36: Privately-Owned Business | I36: 21625 Geer Avenue | J36: Hilmar | K36: 95324 | L36: Merced | M36: 37.39599 | N36: -120.87862 | O36: Dairy Farms | P36: Dairy Cattle and Milk Production | Q36: ANIWSTCOWS | R36: ANIMALWASTE | S36: 5B24NC00136 | T36: 334765 | U36: Enrollee - WDR | V36: Enrollee Under Dairy GO for Jorge, Luis & Maria - Mario and Christina Nunes Dairy | W36: 03/06/2017 - Op. has changed - ak On 12/30/08, we received a request for operator transfer approval for the dairy located at 21625 Geer Ave. The operator transfer approval is effective 03/16/09 - jv | X36: R5-2013-0122 | Y36: Active | Z36: 43411 | AA36: 39262 | AB36: 10/02/2018 | AC36: 10 - Confined animal feeding facility | AD36: Lamyae Zinebi | AE36: 1 | AF36: 327 | AG36: Mature dairy cattle | AH36: Dairies | AI36: 0 | AJ36: N
A37: 5S | B37: 705274 | C37: B & D Dairy | D37: Growing | E37: Animal Feeding | F37: Agricultural | G37: Huff, Eric | H37: Privately-Owned Business | I37: 9579 Hultberg Road | J37: Hilmar | K37: 95324 | L37: Merced | M37: 37.42649 | N37: -120.89554 | O37: Dairy Farms | P37: Dairy Cattle and Milk Production | Q37: ANIWSTCOWS | R37: ANIMALWASTE | S37: 5B24NC00139 | T37: 334768 | U37: Enrollee - WDR | V37: Enrollee Under Dairy GO for Huff, Eric - B & D Dairy | X37: R5-2013-0122 | Y37: Active | Z37: 43411 | AA37: 39262 | AB37: 10/02/2018 | AC37: 10 - Confined animal feeding facility | AD37: Lamyae Zinebi | AE37: 1 | AF37: 654 | AG37: Heifers (non dairy affiliated) | AH37: Dairies | AI37: 1200 | AJ37: N
A38: 5S | B38: 705276 | C38: Silveira Dairy Inc. | D38: Growing | E38: Animal Feeding | F38: Agricultural | G38: Silveira, Frank | H38: Privately-Owned Business | I38: 20271 Johnson Avenue | J38: Hilmar | K38: 95324 | L38: Merced | M38: 37.43333 | N38: -120.85196 | O38: Dairy Farms | P38: Dairy Cattle and Milk Production | Q38: ANIWSTCOWS | R38: ANIMALWASTE | S38: 5B24NC00140 | T38: 334769 | U38: Enrollee - WDR | V38: Enrollee Under Dairy GO for Silveira, Frank - Silveira Dairy, Inc. | X38: R5-2013-0122 | Y38: Active | Z38: 43411 | AA38: 39262 | AB38: 10/02/2018 | AC38: 10 - Confined animal feeding facility | AD38: Lamyae Zinebi | AE38: 1 | AF38: 654 | AG38: Mature dairy cattle | AH38: Dairies | AI38: 400 | AJ38: Y
A39: 5S | B39: 705277 | C39: Jade Jersey Dairy | D39: Growing | E39: Animal Feeding | F39: Agricultural | G39: Ahlem, James & Carol | H39: Privately-Owned Business | I39: 20326 Johnson Avenue | J39: Hilmar | K39: 95324 | L39: Merced | M39: 37.4333 | N39: -120.85581 | O39: Dairy Farms | P39: Dairy Cattle and Milk Production | Q39: ANIWSTCOWS | R39: ANIMALWASTE | S39: 5B24NC00141 | T39: 334770 | U39: Enrollee - WDR | V39: Enrollee Under Dairy Gen Order for Ahlem, James & Carol - Jade Jersey Dairy | X39: R5-2013-0122 | Y39: Active | Z39: 43411 | AA39: 39262 | AB39: 10/02/2018 | AC39: 10 - Confined animal feeding facility | AD39: Lamyae Zinebi | AE39: 1 | AF39: 654 | AG39: Mature dairy cattle | AH39: Dairies | AI39: 450 | AJ39: Y
A40: 5S | B40: 705279 | C40: Live Oak Dairy A | D40: Growing | E40: Animal Feeding | F40: Agricultural | G40: Nyman, Brad | H40: Privately-Owned Business | I40: 21052 Johnson Avenue | J40: Hilmar | K40: 95324 | L40: Merced | M40: 37.43355 | N40: -120.87067 | O40: Dairy Farms | P40: Dairy Cattle and Milk Production | Q40: ANIWSTCOWS | R40: ANIMALWASTE | S40: 5B24NC00142 | T40: 334771 | U40: Enrollee - WDR | V40: Enrollee Under Dairy GO for Nyman, Brad - Live Oak Dairy A | X40: R5-2013-0122 | Y40: Active | Z40: 42647 | AA40: 39262 | AB40: 10/02/2018 | AC40: 10 - Confined animal feeding facility | AD40: Lamyae Zinebi | AE40: 1 | AF40: 654 | AG40: Mature dairy cattle | AH40: Dairies | AI40: 475 | AJ40: Y
...

Sheet Input
A1: FACILITY ID | B1: ='A & M De Souza Dairy'!B1 -> 203907 | C1: ='Silva Dairy Farms #3A'!B1 -> 209495 | D1: ='Joe Borba Dairy Inc.'!B1 -> 210049 | E1: ='Ken Van Foeken Dairy #2'!B1 -> 218891 | F1: ='Da Rosa Dairy'!B1 -> 218992 | G1: ='J_D Brasil Dairy'!#REF! -> #REF! | H1: ='River Rock Ranch LLC'!L1 -> 220560 | I1: ='Double Cross #3'!L1 -> 221709 | J1: ='Edward Nunes Dairy'!L1 -> 222320 | K1: ='Gomes Dairy'!#REF! -> #REF! | L1: ='Roest Family Dairy'!L1 -> 226601 | M1: ='Gil Tex Dairy'!L1 -> 227158 | N1: ='GJ Silva'!L1 -> 227211 | O1: ='Hilmar Holsteins Inc.'!L1 -> 230428 | P1: ='Jordao Dairy'!L1 -> 233735 | Q1: ='Cross Creek Dairy'!L1 -> 233749 | R1: ='Double Cross #2'!L1 -> 233757 | S1: ='LarryPetersonDairyFarms#2'!L1 -> 233895 | T1: ='Fire_Lake Jerseys #2'!L1 -> 233934 | U1: ='Lumar Dairy Farms'!L1 -> 237694 | V1: ='CMA Livestock'!L1 -> 239367 | W1: ='Fire Lakes Jerseys'!L1 -> 251780 | X1: ='Rick Jones Farms'!L1 -> 252667 | Y1: ='Silveira Holsteins'!L1 -> 257092 | Z1: ='Diamond B Dairy'!L1 -> 263088 | AA1: ='Azevedo Dairy'!L1 -> 264484 | AB1: ='Valsigna Dairy'!L1 -> 272502 | AC1: =WickstromJerseyFarmsInc.!L1 -> 705196 | AD1: ='Diniz Dairy'!L1 -> 705203 | AE1: ='Crane Dairy Inc.'!L1 -> 705219 | AF1: ='GM Silva Dairies #2'!L1 -> 705229 | AG1: ='Joe Oliveira Dairy'!#REF! -> #REF! | AH1: ='Vierra Dairy Farms #3'!L1 -> 705238 | AI1: ='Nelson Dairy'!L1 -> 705241 | AJ1: ='Mario&ChristinaNunesDairy'!L1 -> 705247 | AK1: ='B & D Dairy'!L1 -> 705274 | AL1: ='Silveira Dairy Inc.'!L1 -> 705276 | AM1: ='Jade Jersey Dairy'!L1 -> 705277 | AN1: ='Live Oak Dairy A'!L1 -> 705279 | AO1: ='T & M Borba Dairy'!L1 -> 705281 | AP1: ='Oslo Dairy'!L1 -> 705283 | AQ1: ='Kronberg Facility'!L1 -> 705286 | AR1: ='Ken Van Foeken Dairy'!L1 -> 705288 | AS1: ='Amaral Dairy Farms'!L1 -> 705290 | AT1: ='B_6 Dairy'!L1 -> 705294 | AU1: ='6D Dores Dairy'!L1 -> 705296 | AV1: ='Fanelli Dairy'!L1 -> 705297 | AW1: ='Joao Sousa Dairy'!L1 -> 705298 | AX1: ='Vierra Dairy Farms #2'!L1 -> 705300 | AY1: ='Michael Brasil Dairy'!L1 -> 705503 | AZ1: ='Anchor J Dairy'!L1 -> 705505 | BA1: ='Oliveira Dairy'!L1 -> 705508 | BB1: ='Souza Bros Dairy'!L1 -> 705510 | BC1: ='Miguel Family Dairy'!L1 -> 705512 | BD1: ='Dias Family Dairy'!L1 -> 705514 | BE1: ='Empty was A_D Dairy'!L1 -> 705515 | BF1: ='Michael Brasil Dairy #2'!L1 -> 705519 | BG1: ='F & A Lemos Dairy'!L1 -> 705523 | BH1: ='Alves & Son Dairy #2'!L1 -> 705524 | BI1: ='Golf Link RanchesLLC'!L1 -> 705526 | BJ1: ='Triple M Jerseys'!L1 -> 705527 | BK1: ='Jose & Teresa Soares Dairy'!L1 -> 705528 | BL1: ='MachadoGabriel&SonsDairy'!L1 -> 705530 | BM1: ='Hawkins Ranch'!L1 -> 705775 | BN1: ='Silva Dairy Farms #3B'!L1 -> 705776 | BO1: =AhlemFarmsPartnership!L1 -> 706122 | BP1: ='Vierra Dairy Farms #4'!L1 -> 706124 | BQ1: ='CaliforniaDairyFarms LLC'!L1 -> 706125 | BR1: ='Larry Peterson Dairy'!L1 -> 706126 | BS1: ='Joe Egli&Sons Dairy'!L1 -> 706128 | BT1: ='CMA Livestock #2'!L1 -> 706129 | BU1: ='Valentine Dairy'!L1 -> 706131 | BV1: ='CMC Jerseys LLC'!L1 -> 706132 | BW1: ='Fanelli_Fanelli Brothers'!L1 -> 706133 | BX1: ='Martins Bros Dairy'!L1 -> 706135 | BY1: ='Gomes Heifer Ranch'!L1 -> 706422 | BZ1: ='Ed Hirdes Dairy'!B1 -> 706423 | CA1: ='Dematos Dairy'!L1 -> 706424 | CB1: ='Carlos Estacio&Sons Dairy'!L1 -> 706431 | CC1: ='Live Oak Dairy G'!L1 -> 706447 | CD1: ='Verissimo Facility'!L1 -> 706449 | CE1: ='Double Cross Dairy'!L1 -> 706450 | CF1: ='Double Cross #4'!L1 -> 706453 | CG1: ='King Dairy'!L1 -> 706454 | CH1: ='Vieira Livestock'!L1 -> 706459 | CI1: ='AldenPeterson&SonsDairy Inc.'!L1 -> 706462 | CJ1: ='John Nunes Dairy #3'!L1 -> 706464 | CK1: ='Roestar Dairy'!L1 -> 706477 | CL1: ='Luis M. Azevedo Dairy'!L1 -> 706496 | CM1: ='Arlinda Holsteins'!L1 -> 706497 | CN1: ='Robert Gioletti & Sons Dairy'!L1 -> 706498 | CO1: ='Carl Vieira Dairy'!L1 -> 706499 | CP1: ='John Brasil & Sons Dairy'!L1 -> 706505 | CQ1: ='John Brasil Dairy #3'!L1 -> 706506 | CR1: ='KMA Dairy'!L1 -> 706508 | CS1: ='Sallaberry Ranch'!L1 -> 706509 | CT1: ='Alfred C Nunes Dairy'!L1 -> 706510 | CU1: ='Jim Vieira & Son Dairy'!L1 -> 706512 | CV1: ='Ehrlich Dairy'!L1 -> 706513 | CW1: ='D&A Brasil Facility'!B1 -> 706514 | CX1: ='Silva''s Holsteins'!B1 -> 706515 | CY1: ='G J Silva #3'!B1 -> 706518 | CZ1: ='Jim Vieira and Son Dairy #2'!L1 -> 706519 | DA1: ='Johal Dairy'!L1 -> 706520 | DB1: ='A & G Azevedo Dairy'!L1 -> 706522 | DC1: ='Gentle Breezes Dairy'!L1 -> 706524 | DD1: ='Joe Sousa Jr Dairy'!L1 -> 706527 | DE1: ='John Brasil Heifers'!L1 -> 706529 | DF1: ='MHF Dairy'!L1 -> 706533 | DG1: ='Brindiero&DanbomDairyFarms'!L1 -> 706536 | DH1: ='A&C Machado Dairy #2'!L1 -> 706539 | DI1: ='J & J Toste DairyInc.'!L1 -> 706549 | DJ1: ='Bar Vee DairyInc.'!L1 -> 706551 | DK1: ='Railside Jersey FarmsLLC'!L1 -> 706555 | DL1: ='Manuel Azevedo Dairy'!L1 -> 706556 | DM1: ='Sousa Family Dairy'!L1 -> 706558 | DN1: ='UC Davis Animal Science Dairy'!L1 -> 706578 | DO1: ='Garcia''s Registered Jerseys'!L1 -> 706579 | DP1: ='Lucio Corral Cattle'!L1 -> 706582 | DQ1: ='Wickstrom Dairy Inc'!B1 -> 706583 | DR1: ='Sam Kooistra Dairy'!L1 -> 706584 | DS1: ='Vitorino & Sons Dairy'!L1 -> 706586 | DT1: ='Valley Cross Dairy'!L1 -> 706587 | DU1: ='John Brasil & Sons Dairy #2'!L1 -> 706588 | DV1: ='Pepper Dairy'!L1 -> 706945 | DW1: ='Clauss Dairy Farms'!L1 -> 726796 | DX1: ='Dairy Central Heifers'!L1 -> 727868 | DY1: ='Yosemite Jersey Dairy'!L1 -> 727901 | DZ1: ='Sunwest Jersey Dairy'!L1 -> 730625 | EA1: ='N & C Silveira Dairy'!L1 -> 730634 | EB1: ='Nyman Brothers Dairy'!L1 -> 735382 | EC1: ='Broder Farms'!L1 -> 736896 | ED1: ='Borba Dairy Farms'!L1 -> 736922 | EE1: ='Charles Ahlem Ranch'!L1 -> 743935 | EF1: ='James Ahlem Dairy'!L1 -> 743941 | EG1: ='Nylund Dairy Farms'!L1 -> 743944 | EH1: ='Vierra Ranch Dairy'!L1 -> 743948 | EI1: ='Joe O Rocha Dairy Inc.'!L1 -> 745165 | EJ1: ='Alves & Son Dairy'!L1 -> 745172 | EK1: ='3A Teixeira Dairy'!L1 -> 745179 | EL1: ='Denizma_Bud Postma Dairy'!L1 -> 745430 | EM1: ='Couco Creek Dairy'!L1 -> 782059 | EN1: ='Clausen Dairy'!L1 -> 810786
A2: FACILITY NAME | B2: ='A & M De Souza Dairy'!B2 -> A & M De Souza Dairy | C2: ='Silva Dairy Farms #3A'!B2 -> Silva Dairy Farms #3A | D2: ='Joe Borba Dairy Inc.'!B2 -> Joe Borba Dairy, Inc. | E2: ='Ken Van Foeken Dairy #2'!B2 -> Ken Van Foeken Dairy #2 | F2: ='Da Rosa Dairy'!B2 -> Da Rosa Dairy | G2: ='J_D Brasil Dairy'!#REF! -> #REF! | H2: ='River Rock Ranch LLC'!L2 -> River Rock Ranch, LLC | I2: ='Double Cross #3'!L2 -> Double Cross #3 | J2: ='Edward Nunes Dairy'!L2 -> Edward Nunes Dairy | K2: ='Gomes Dairy'!#REF! -> #REF! | L2: ='Roest Family Dairy'!L2 -> Roest Family Dairy | M2: ='Gil Tex Dairy'!L2 -> Gil Tex Dairy | N2: ='GJ Silva'!L2 -> GJ Silva | O2: ='Hilmar Holsteins Inc.'!L2 -> Hilmar Holsteins, Inc. | P2: ='Jordao Dairy'!L2 -> Jordao Dairy | Q2: ='Cross Creek Dairy'!L2 -> Vierra Dairy LLC #4 | R2: ='Double Cross #2'!L2 -> Double Cross #2 | S2: ='LarryPetersonDairyFarms#2'!L2 -> Larry B. Peterson Dairy Farms #2 | T2: ='Fire_Lake Jerseys #2'!L2 -> Fire-Lake Jerseys #2 | U2: ='Lumar Dairy Farms'!L2 -> Lumar Dairy Farms | V2: ='CMA Livestock'!L2 -> Double Cross #5 | W2: ='Fire Lakes Jerseys'!L2 -> Fire Lakes Jerseys | X2: ='Rick Jones Farms'!L2 -> Rick Jones Farms | Y2: ='Silveira Holsteins'!L2 -> Silveira Holsteins | Z2: ='Diamond B Dairy'!L2 -> Diamond B Dairy | AA2: ='Azevedo Dairy'!L2 -> Azevedo Dairy | AB2: ='Valsigna Dairy'!L2 -> Valsigna Dairy | AC2: =WickstromJerseyFarmsInc.!L2 -> Wickstrom Jersey Farms, Inc. | AD2: ='Diniz Dairy'!L2 -> Diniz Dairy | AE2: ='Crane Dairy Inc.'!L2 -> Crane Dairy, Inc. | AF2: ='GM Silva Dairies #2'!L2 -> GM Silva Dairies #2 | AG2: ='Joe Oliveira Dairy'!#REF! -> #REF! | AH2: ='Vierra Dairy Farms #3'!L2 -> Vierra Dairy Farms #3 | AI2: ='Nelson Dairy'!L2 -> Nelson Dairy | AJ2: ='Mario&ChristinaNunesDairy'!L2 -> Luis & Maria Jorge Dairy | AK2: ='B & D Dairy'!L2 -> B & D Dairy | AL2: ='Silveira Dairy Inc.'!L2 -> Live Oak Dairy H | AM2: ='Jade Jersey Dairy'!L2 -> Jade Jersey Dairy | AN2: ='Live Oak Dairy A'!L2 -> Live Oak Dairy A | AO2: ='T & M Borba Dairy'!L2 -> T & M Borba Dairy | AP2: ='Oslo Dairy'!L2 -> Oslo Dairy | AQ2: ='Kronberg Facility'!L2 -> Kronberg Facility | AR2: ='Ken Van Foeken Dairy'!L2 -> Ken Van Foeken Dairy | AS2: ='Amaral Dairy Farms'!L2 -> Amaral Dairy Farms | AT2: ='B_6 Dairy'!L2 -> B-6 Dairy | AU2: ='6D Dores Dairy'!L2 -> 6D Dores Dairy | AV2: ='Fanelli Dairy'!L2 -> Fanelli Dairy | AW2: ='Joao Sousa Dairy'!L2 -> Joao Sousa Dairy | AX2: ='Vierra Dairy Farms #2'!L2 -> Vierra Dairy Farms #2 | AY2: ='Michael Brasil Dairy'!L2 -> Borba Cattle Company, LP | AZ2: ='Anchor J Dairy'!L2 -> Anchor J Dairy | BA2: ='Oliveira Dairy'!L2 -> Oliveira Dairy | BB2: ='Souza Bros Dairy'!L2 -> Souza Bros Dairy | BC2: ='Miguel Family Dairy'!L2 -> Miguel Family Dairy | BD2: ='Dias Family Dairy'!L2 -> Dias Family Dairy | BE2: ='Empty was A_D Dairy'!L2 -> Empty (was A-D Dairy) | BF2: ='Michael Brasil Dairy #2'!L2 -> Michael Brasil Dairy #2 | BG2: ='F & A Lemos Dairy'!L2 -> F & A Lemos Dairy | BH2: ='Alves & Son Dairy #2'!L2 -> Alves & Son Dairy #2 | BI2: ='Golf Link RanchesLLC'!L2 -> Golf Link Ranches, LLC | BJ2: ='Triple M Jerseys'!L2 -> Triple M Jerseys | BK2: ='Jose & Teresa Soares Dairy'!L2 -> Jose & Teresa Soares Dairy | BL2: ='MachadoGabriel&SonsDairy'!L2 -> Machado Gabriel & Sons Dairy | BM2: ='Hawkins Ranch'!L2 -> Hawkins Ranch | BN2: ='Silva Dairy Farms #3B'!L2 -> Silva Dairy Farms #3B | BO2: =AhlemFarmsPartnership!L2 -> Ahlem Farms Partnership | BP2: ='Vierra Dairy Farms #4'!L2 -> Vierra Heifer Ranch (Dairy) | BQ2: ='CaliforniaDairyFarms LLC'!L2 -> California Dairy Farms, LLC | BR2: ='Larry Peterson Dairy'!L2 -> Double Cross #6 | BS2: ='Joe Egli&Sons Dairy'!L2 -> Joe Egli and Sons Dairy | BT2: ='CMA Livestock #2'!L2 -> CMA Livestock #2 | BU2: ='Valentine Dairy'!L2 -> Valentine Dairy | BV2: ='CMC Jerseys LLC'!L2 -> CMC Jerseys LLC | BW2: ='Fanelli_Fanelli Brothers'!L2 -> Fanelli Dairy - Fanelli Brothers | BX2: ='Martins Bros Dairy'!L2 -> Martins Bros Dairy | BY2: ='Gomes Heifer Ranch'!L2 -> Blaker Heifer Ranch | BZ2: ='Ed Hirdes Dairy'!B2 -> Ed Hirdes Dairy | CA2: ='Dematos Dairy'!L2 -> Dematos Dairy | CB2: ='Carlos Estacio&Sons Dairy'!L2 -> Carlos Estacio & Sons Dairy | CC2: ='Live Oak Dairy G'!L2 -> Live Oak Dairy G | CD2: ='Verissimo Facility'!L2 -> Verissimo Facility | CE2: ='Double Cross Dairy'!L2 -> Double Cross Dairy | CF2: ='Double Cross #4'!L2 -> Double Cross #4 | CG2: ='King Dairy'!L2 -> King Dairy | CH2: ='Vieira Livestock'!L2 -> Vieira Livestock | CI2: ='AldenPeterson&SonsDairy Inc.'!L2 -> Alden Peterson & Sons Dairy, Inc. | CJ2: ='John Nunes Dairy #3'!L2 -> S & S 2 Dairy | CK2: ='Roestar Dairy'!L2 -> Roestar Dairy | CL2: ='Luis M. Azevedo Dairy'!L2 -> Luis M. Azevedo Dairy | CM2: ='Arlinda Holsteins'!L2 -> Arlinda Holsteins | CN2: ='Robert Gioletti & Sons Dairy'!L2 -> Robert Gioletti & Sons Dairy | CO2: ='Carl Vieira Dairy'!L2 -> Carl Vieira Dairy | CP2: ='John Brasil & Sons Dairy'!L2 -> John Brasil & Sons Dairy | CQ2: ='John Brasil Dairy #3'!L2 -> John Brasil Dairy #3 | CR2: ='KMA Dairy'!L2 -> KMA Dairy | CS2: ='Sallaberry Ranch'!L2 -> Sallaberry Ranch | CT2: ='Alfred C Nunes Dairy'!L2 -> Alfred C Nunes Dairy | CU2: ='Jim Vieira & Son Dairy'!L2 -> GJC Dairy, Inc. | CV2: ='Ehrlich Dairy'!L2 -> Ehrlich Dairy | CW2: ='D&A Brasil Facility'!B2 -> D&A Brasil Facility | CX2: ='Silva''s Holsteins'!B2 -> Silva's Holsteins | CY2: ='G J Silva #3'!B2 -> #N/A | CZ2: ='Jim Vieira and Son Dairy #2'!L2 -> Jim Vieira and Son Dairy #2 | DA2: ='Johal Dairy'!L2 -> Johal Dairy | DB2: ='A & G Azevedo Dairy'!L2 -> A & G Azevedo Dairy | DC2: ='Gentle Breezes Dairy'!L2 -> Gentle Breezes Dairy | DD2: ='Joe Sousa Jr Dairy'!L2 -> Joe Sousa Feedlot | DE2: ='John Brasil Heifers'!L2 -> Reis Dairy | DF2: ='MHF Dairy'!L2 -> MHF Dairy | DG2: ='Brindiero&DanbomDairyFarms'!L2 -> Brindiero & Danbom Dairy Farms | DH2: ='A&C Machado Dairy #2'!L2 -> A&C Machado Dairy #2 | DI2: ='J & J Toste DairyInc.'!L2 -> J & J Toste Dairy, Inc. | DJ2: ='Bar Vee DairyInc.'!L2 -> Bar Vee Dairy, Inc. | DK2: ='Railside Jersey FarmsLLC'!L2 -> Cal Farm House | DL2: ='Manuel Azevedo Dairy'!L2 -> Manuel Azevedo Dairy | DM2: ='Sousa Family Dairy'!L2 -> Sousa Family Dairy | DN2: ='UC Davis Animal Science Dairy'!L2 -> UC Davis Animal Science Dairy | DO2: ='Garcia''s Registered Jerseys'!L2 -> Garcia's Registered Jerseys | DP2: ='Lucio Corral Cattle'!L2 -> Lucio Corral Cattle | DQ2: ='Wickstrom Dairy Inc'!B2 -> Wickstrom Dairy Inc | DR2: ='Sam Kooistra Dairy'!L2 -> Sam Kooistra Dairy | DS2: ='Vitorino & Sons Dairy'!L2 -> Vitorino & Sons Dairy | DT2: ='Valley Cross Dairy'!L2 -> Valley Cross Dairy | DU2: ='John Brasil & Sons Dairy #2'!L2 -> John Brasil & Sons Dairy #2 | DV2: ='Pepper Dairy'!L2 -> Pepper Dairy | DW2: ='Clauss Dairy Farms'!L2 -> Clauss Dairy Farms | DX2: ='Dairy Central Heifers'!L2 -> Dairy Central Heifers | DY2: ='Yosemite Jersey Dairy'!L2 -> River Rock Ranch, LLC | DZ2: ='Sunwest Jersey Dairy'!L2 -> Sunwest Jersey Dairy | EA2: ='N & C Silveira Dairy'!L2 -> N & C Silveira Dairy | EB2: ='Nyman Brothers Dairy'!L2 -> Nyman Brothers Dairy | EC2: ='Broder Farms'!L2 -> Broder Farms | ED2: ='Borba Dairy Farms'!L2 -> Borba Dairy Farms | EE2: ='Charles Ahlem Ranch'!L2 -> Charles Ahlem Ranch | EF2: ='James Ahlem Dairy'!L2 -> Gold Medal Ag #1 Dairy | EG2: ='Nylund Dairy Farms'!L2 -> Nylund Dairy Farms | EH2: ='Vierra Ranch Dairy'!L2 -> Vierra Ranch Dairy | EI2: ='Joe O Rocha Dairy Inc.'!L2 -> Joe O Rocha Dairy Inc. | EJ2: ='Alves & Son Dairy'!L2 -> Alves & Son Dairy | EK2: ='3A Teixeira Dairy'!L2 -> 3A Teixeira Dairy | EL2: ='Denizma_Bud Postma Dairy'!L2 -> Denizma Dairy / Bud Postma Dairy | EM2: ='Couco Creek Dairy'!L2 -> Couco Creek Dairy | EN2: ='Clausen Dairy'!L2 -> Clausen Dairy
A3: PLACE ADDRESS | B3: ='A & M De Souza Dairy'!B3 -> 3030 South Central Avenue | C3: ='Silva Dairy Farms #3A'!B3 -> 1499 North Edminster Road | D3: ='Joe Borba Dairy Inc.'!B3 -> 3431 South Moffett Road | E3: ='Ken Van Foeken Dairy #2'!B3 -> 9375 North Washington Road | F3: ='Da Rosa Dairy'!B3 -> 1131 Story Road | G3: ='J_D Brasil Dairy'!#REF! -> #REF! | H3: ='River Rock Ranch LLC'!L3 -> 22846 West Second Avenue | I3: ='Double Cross #3'!L3 -> 11071 Youngstown Road | J3: ='Edward Nunes Dairy'!L3 -> 17399 East Avena Road | K3: ='Gomes Dairy'!#REF! -> #REF! | L3: ='Roest Family Dairy'!L3 -> 2472 Gates Road | M3: ='Gil Tex Dairy'!L3 -> 5601 Mountain View Road | N3: ='GJ Silva'!L3 -> 3107 South Prairie Flower Road | O3: ='Hilmar Holsteins Inc.'!L3 -> 21859 Crane Avenue | P3: ='Jordao Dairy'!L3 -> 6025 South Central Avenue | Q3: ='Cross Creek Dairy'!L3 -> 7965 Washington Road | R3: ='Double Cross #2'!L3 -> 18637 East Bradbury Road | S3: ='LarryPetersonDairyFarms#2'!L3 -> 20775 West American Avenue | T3: ='Fire_Lake Jerseys #2'!L3 -> 10408 West Bradbury Road | U3: ='Lumar Dairy Farms'!L3 -> 7215 South Prairie Flower Road | V3: ='CMA Livestock'!L3 -> 19051 West Williams Avenue | W3: ='Fire Lakes Jerseys'!L3 -> 11301 West Bradbury Road | X3: ='Rick Jones Farms'!L3 -> 1511 Van Clief Road | Y3: ='Silveira Holsteins'!L3 -> 23356 Short Avenue | Z3: ='Diamond B Dairy'!L3 -> 3137 East Tuolumne Road | AA3: ='Azevedo Dairy'!L3 -> 21480 August Avenue | AB3: ='Valsigna Dairy'!L3 -> 6071 North Larson Avenue | AC3: =WickstromJerseyFarmsInc.!L3 -> 5638 Columbus Avenue | AD3: ='Diniz Dairy'!L3 -> 9558 Columbus Avenue | AE3: ='Crane Dairy Inc.'!L3 -> 20633 West Crane Avenue | AF3: ='GM Silva Dairies #2'!L3 -> 20316 West Crane Avenue | AG3: ='Joe Oliveira Dairy'!#REF! -> #REF! | AH3: ='Vierra Dairy Farms #3'!L3 -> 7884 Faith Home Road | AI3: ='Nelson Dairy'!L3 -> 19481 Geer Avenue | AJ3: ='Mario&ChristinaNunesDairy'!L3 -> 21625 Geer Avenue | AK3: ='B & D Dairy'!L3 -> 9579 Hultberg Road | AL3: ='Silveira Dairy Inc.'!L3 -> 20271 Johnson Avenue | AM3: ='Jade Jersey Dairy'!L3 -> 20326 Johnson Avenue | AN3: ='Live Oak Dairy A'!L3 -> 21052 Johnson Avenue | AO3: ='T & M Borba Dairy'!L3 -> 6275 Mitchell Road | AP3: ='Oslo Dairy'!L3 -> 20334 West Oslo Road | AQ3: ='Kronberg Facility'!L3 -> 20777 Riverside Avenue | AR3: ='Ken Van Foeken Dairy'!L3 -> 22338 Short Avenue | AS3: ='Amaral Dairy Farms'!L3 -> 7706 Tegner Road | AT3: ='B_6 Dairy'!L3 -> 22014 Turner Avenue | AU3: ='6D Dores Dairy'!L3 -> 25762 Turner Avenue | AV3: ='Fanelli Dairy'!L3 -> 7689 Washington Road | AW3: ='Joao Sousa Dairy'!L3 -> 18005 Williams Avenue | AX3: ='Vierra Dairy Farms #2'!L3 -> 22682 West Williams Avenue | AY3: ='Michael Brasil Dairy'!L3 -> 18254 First Avenue | AZ3: ='Anchor J Dairy'!L3 -> 24507 First Avenue | BA3: ='Oliveira Dairy'!L3 -> 3991 Lander Avenue | BB3: ='Souza Bros Dairy'!L3 -> 3887 McCullagh Road | BC3: ='Miguel Family Dairy'!L3 -> 20755 West River Road | BD3: ='Dias Family Dairy'!L3 -> 21330 West Second Avenue | BE3: ='Empty was A_D Dairy'!L3 -> 23489 West Second Avenue | BF3: ='Michael Brasil Dairy #2'!L3 -> 4971 Van Clief Road | BG3: ='F & A Lemos Dairy'!L3 -> 14371 East Avenue | BH3: ='Alves & Son Dairy #2'!L3 -> 13831 East Avenue | BI3: ='Golf Link RanchesLLC'!L3 -> 10220 Golf Link Road | BJ3: ='Triple M Jerseys'!L3 -> 1008 North Verduga Road | BK3: ='Jose & Teresa Soares Dairy'!L3 -> 11076 North Vincent Road | BL3: ='MachadoGabriel&SonsDairy'!L3 -> 12464 South Vincent Road | BM3: ='Hawkins Ranch'!L3 -> 5301 North De Angelis Road | BN3: ='Silva Dairy Farms #3B'!L3 -> 1904 Edminster Road | BO3: =AhlemFarmsPartnership!L3 -> 24093 West American Avenue | BP3: ='Vierra Dairy Farms #4'!L3 -> 25511 West American Avenue | BQ3: ='CaliforniaDairyFarms LLC'!L3 -> 18128 American Avenue | BR3: ='Larry Peterson Dairy'!L3 -> 21189 American Avenue | BS3: ='Joe Egli&Sons Dairy'!L3 -> 21810 West August Avenue | BT3: ='CMA Livestock #2'!L3 -> 23970 West August Avenue | BU3: ='Valentine Dairy'!L3 -> 20717 Bloss Avenue | BV3: ='CMC Jerseys LLC'!L3 -> 23204 Bloss Avenue | BW3: ='Fanelli_Fanelli Brothers'!L3 -> 23839 Bloss Avenue | BX3: ='Martins Bros Dairy'!L3 -> 6041 Central Avenue | BY3: ='Gomes Heifer Ranch'!L3 -> 737 South Blaker Road | BZ3: ='Ed Hirdes Dairy'!B3 -> 2131 South Blaker Road | CA3: ='Dematos Dairy'!L3 -> 931 South Blaker Road | CB3: ='Carlos Estacio&Sons Dairy'!L3 -> 8900 West Bradbury Road | CC3: ='Live Oak Dairy G'!L3 -> 730 Bystrum | CD3: ='Verissimo Facility'!L3 -> 6125 South Central Avenue | CE3: ='Double Cross Dairy'!L3 -> 7025 South Central Avenue | CF3: ='Double Cross #4'!L3 -> 6006 South Central Avenue | CG3: ='King Dairy'!L3 -> 5524 South Central Avenue | CH3: ='Vieira Livestock'!L3 -> 3800 South Central Avenue | CI3: ='AldenPeterson&SonsDairy Inc.'!L3 -> 1431 North Central Avenue | CJ3: ='John Nunes Dairy #3'!L3 -> 5324 Clayton Road | CK3: ='Roestar Dairy'!L3 -> 10407 West Bradbury Road | CL3: ='Luis M. Azevedo Dairy'!L3 -> 11412 West Main Street | CM3: ='Arlinda Holsteins'!L3 -> 6325 West Main Street | CN3: ='Robert Gioletti & Sons Dairy'!L3 -> 10213 West Main Street | CO3: ='Carl Vieira Dairy'!L3 -> 1000 North Mitchell Road | CP3: ='John Brasil & Sons Dairy'!L3 -> 2613 South Mitchell Road | CQ3: ='John Brasil Dairy #3'!L3 -> 1707 South Mitchell Road | CR3: ='KMA Dairy'!L3 -> 539 South Morgan Road | CS3: ='Sallaberry Ranch'!L3 -> 5608 South Morgan Road | CT3: ='Alfred C Nunes Dairy'!L3 -> 5119 South Morgan Road | CU3: ='Jim Vieira & Son Dairy'!L3 -> 2401 Newman Road | CV3: ='Ehrlich Dairy'!L3 -> 5725 Ehrlich Road | CW3: ='D&A Brasil Facility'!B3 -> 4218 South Prairie Flower Road | CX3: ='Silva''s Holsteins'!B3 -> 6706 Elaine Road | CY3: ='G J Silva #3'!B3 -> #N/A | CZ3: ='Jim Vieira and Son Dairy #2'!L3 -> 3100 South Prairie Flower Road | DA3: ='Johal Dairy'!L3 -> 315 North Prairie Flower Road | DB3: ='A & G Azevedo Dairy'!L3 -> 536 North Prairie Flower Road | DC3: ='Gentle Breezes Dairy'!L3 -> 4419 South Faith Home Road | DD3: ='Joe Sousa Jr Dairy'!L3 -> 1519 North Prairie Flower Road | DE3: ='John Brasil Heifers'!L3 -> 6730 West Harding | DF3: ='MHF Dairy'!L3 -> 501 South Story Road | DG3: ='Brindiero&DanbomDairyFarms'!L3 -> 5831 South Tegner Road | DH3: ='A&C Machado Dairy #2'!L3 -> 619 South Vincent Road | DI3: ='J & J Toste DairyInc.'!L3 -> 2207 South Walnut Road | DJ3: ='Bar Vee DairyInc.'!L3 -> 3031 North Washington Road | DK3: ='Railside Jersey FarmsLLC'!L3 -> 6816 North Washington Road | DL3: ='Manuel Azevedo Dairy'!L3 -> 2800 White Road | DM3: ='Sousa Family Dairy'!L3 -> 12801 West Bradbury Road | DN3: ='UC Davis Animal Science Dairy'!L3 -> 201 Dairy Road | DO3: ='Garcia''s Registered Jerseys'!L3 -> 1018 Hickman Road | DP3: ='Lucio Corral Cattle'!L3 -> 207 Holland Drive | DQ3: ='Wickstrom Dairy Inc'!B3 -> 5612 Hultberg Road | DR3: ='Sam Kooistra Dairy'!L3 -> 5837 Hultberg Road | DS3: ='Vitorino & Sons Dairy'!L3 -> 3918 South Kilroy Road | DT3: ='Valley Cross Dairy'!L3 -> 9500 West Linwood Avenue | DU3: ='John Brasil & Sons Dairy #2'!L3 -> 9018 West Linwood Avenue | DV3: ='Pepper Dairy'!L3 -> 13942 North Pepper Street | DW3: ='Clauss Dairy Farms'!L3 -> 21670 Bloss Avenue | DX3: ='Dairy Central Heifers'!L3 -> 10119 West August Road | DY3: ='Yosemite Jersey Dairy'!L3 -> 21522 Geer Avenue | DZ3: ='Sunwest Jersey Dairy'!L3 -> 22270 Bloss Avenue | EA3: ='N & C Silveira Dairy'!L3 -> 6025 Hultberg Road | EB3: ='Nyman Brothers Dairy'!L3 -> 20445 August Avenue | EC3: ='Broder Farms'!L3 -> 22245 August Avenue | ED3: ='Borba Dairy Farms'!L3 -> 5297 Kelley Road | EE3: ='Charles Ahlem Ranch'!L3 -> 23546 West American Avenue | EF3: ='James Ahlem Dairy'!L3 -> 9483 Columbus Avenue | EG3: ='Nylund Dairy Farms'!L3 -> 20723 Geer Avenue | EH3: ='Vierra Ranch Dairy'!L3 -> 23160 Williams Avenue | EI3: ='Joe O Rocha Dairy Inc.'!L3 -> 18451 East Bradbury Road | EJ3: ='Alves & Son Dairy'!L3 -> 13745 Newport Road | EK3: ='3A Teixeira Dairy'!L3 -> 12926 North Vincent Road | EL3: ='Denizma_Bud Postma Dairy'!L3 -> 6249 Parker Road | EM3: ='Couco Creek Dairy'!L3 -> 3303 South Washington Road | EN3: ='Clausen Dairy'!L3 -> 18851 East Clausen Road
